Workbook

Sheet Raw_Data
A1: Invoice_Number | B1: Sale_Date | C1: Année | D1: Client_ID | E1: Product_Code | F1: Product_Name | G1: Category | H1: Quantity | I1: Unit_Price | J1: Amount | K1: Montant Recalculé | L1: Ecarts | M1: Country | N1: Channel
A2: 2024001000 | B2: 45394 | C2: =YEAR(B2) -> 2024 | D2: CLIENT_0042 | E2: PROD_004 | F2: Desk Chair | G2: Furniture | H2: 4 | I2: 361.33 | J2: 1445.32 | K2: =I2*H2 -> 1445.32 | L2: =J2-K2 -> 0 | M2: Belgium | N2: Retail
A3: 2024001001 | B3: 45506 | C3: =YEAR(B3) -> 2024 | D3: CLIENT_0088 | E3: PROD_005 | F3: Standing Desk | G3: Furniture | H3: 2 | I3: 645.69 | J3: 1291.38 | K3: =I3*H3 -> 1291.38 | L3: =J3-K3 -> 0 | M3: Switzerland | N3: B2B
A4: 2024001002 | B4: 45657 | C4: =YEAR(B4) -> 2024 | D4: CLIENT_0258 | E4: PROD_008 | F4: Desk Lamp | G4: Furniture | H4: 3 | I4: 77.68 | J4: 233.04 | K4: =I4*H4 -> 233.04 | L4: =J4-K4 -> 0 | M4: Italy | N4: Online
A5: 2024001003 | B5: 45605 | C5: =YEAR(B5) -> 2024 | D5: CLIENT_0022 | E5: PROD_009 | F5: Phone Stand | G5: Accessories | H5: 1 | I5: 24.34 | J5: 24.34 | K5: =I5*H5 -> 24.34 | L5: =J5-K5 -> 0 | M5: Sweden | N5: Reseller
A6: 2024001004 | B6: 45479 | C6: =YEAR(B6) -> 2024 | D6: CLIENT_0271 | E6: PROD_003 | F6: USB-C Cable | G6: Electronics | H6: 1 | I6: 14.98 | J6: 14.98 | K6: =I6*H6 -> 14.98 | L6: =J6-K6 -> 0 | M6: Italy | N6: B2B
A7: 2024001005 | B7: 45426 | C7: =YEAR(B7) -> 2024 | D7: CLIENT_0021 | E7: PROD_009 | F7: Phone Stand | G7: Accessories | H7: 1 | I7: 25.44 | J7: 25.44 | K7: =I7*H7 -> 25.44 | L7: =J7-K7 -> 0 | M7: Spain | N7: Online
A8: 2024001006 | B8: 45607 | C8: =YEAR(B8) -> 2024 | D8: CLIENT_0014 | E8: PROD_002 | F8: Wireless Mouse | G8: Electronics | H8: 1 | I8: 46.75 | J8: 46.75 | K8: =I8*H8 -> 46.75 | L8: =J8-K8 -> 0 | M8: Switzerland | N8: B2B
A9: 2024001007 | B9: 45326 | C9: =YEAR(B9) -> 2024 | D9: CLIENT_0206 | E9: PROD_001 | F9: Laptop Pro | G9: Electronics | H9: 1 | I9: 1133.93 | J9: 1133.93 | K9: =I9*H9 -> 1133.93 | L9: =J9-K9 -> 0 | M9: Switzerland | N9: Reseller
A10: 2024001008 | B10: 45293 | C10: =YEAR(B10) -> 2024 | D10: CLIENT_0054 | E10: PROD_010 | F10: Webcam HD | G10: Electronics | H10: 2 | I10: 80.2 | J10: 160.4 | K10: =I10*H10 -> 160.4 | L10: =J10-K10 -> 0 | M10: Spain | N10: Retail
A11: 2024001009 | B11: 45642 | C11: =YEAR(B11) -> 2024 | D11: CLIENT_0271 | E11: PROD_008 | F11: Desk Lamp | G11: Furniture | H11: 2 | I11: 75.82 | J11: 151.64 | K11: =I11*H11 -> 151.64 | L11: =J11-K11 -> 0 | M11: Austria | N11: Retail
A12: 2024001010 | B12: 45587 | C12: =YEAR(B12) -> 2024 | D12: CLIENT_0213 | E12: PROD_002 | F12: Wireless Mouse | G12: Electronics | H12: 2 | I12: 46.04 | J12: 92.08 | K12: =I12*H12 -> 92.08 | L12: =J12-K12 -> 0 | M12: Austria | N12: Online
A13: 2024001011 | B13: 45306 | C13: =YEAR(B13) -> 2024 | D13: CLIENT_0065 | E13: PROD_009 | F13: Phone Stand | G13: Accessories | H13: 5 | I13: 25.11 | J13: 125.55 | K13: =I13*H13 -> 125.55 | L13: =J13-K13 -> 0 | M13: Switzerland | N13: Online
... A5001: 2024005999 | B5001: 45520 | C5001: =YEAR(B5001) -> 2024 | D5001: CLIENT_0284 | E5001: PROD_009 | F5001: Phone Stand | G5001: Accessories | H5001: 4 | I5001: 24.93 | J5001: 99.72 | K5001: =I5001*H5001 -> 99.72 | L5001: =J5001-K5001 -> 0 | M5001: Switzerland | N5001: Reseller

Sheet Insights
A1: Tests de la qualité des données
A5: TEST 1 : Chiffre d'affaires total
A6: Chiffre d'affaires total (€) | B6: =SUM(Raw_Data!K2:K5001) -> 2728759.5
A8: TEST 2 : Nombre de transactions
A9: Nombre de transactions | B9: =COUNTA(Raw_Data!A2:A5001) -> 5000
A11: TEST 3 : Montants négatifs (Risque de fraude)
A12: Nombre de montants négatifs | B12: =COUNTIF(Raw_Data!K2:K5001,"<0") -> 0
A13: Montant négatif total | B13: =SUMIF(Raw_Data!K2:K5001,"<0") -> 0
A15: TEST 4 : Montants nuls (Qualité des données)
A16: Nombre de montants nuls | B16: =COUNTIF(Raw_Data!K2:K5001,"=0") -> 20
A18: TEST 5 : Factures en double
A19: Factures uniques | B19: 4928
A20: Total des transactions | B20: 5000
A21: Nombre de doublons | B21: 72
A23: TEST 6 : Transactions hors période ( Cut-off)
A24: Transactions 2023 | B24: =COUNTIF(Raw_Data!C2:C5001,"2023") -> 15
A25: Transactions 2025 | B25: =COUNTIF(Raw_Data!C3:C5002,"2025") -> 0
A27: TEST 7 : Valeur moyenne des transactions
A28: Montant moyen (€) | B28: =AVERAGE(Raw_Data!K2:K5001) -> 545.7519
A29: Montant médian (€) | B29: =MEDIAN(Raw_Data!K2:K5001) -> 195.79
A31: TEST 8 : Concentration des clients
A32: Clients uniques | B32: =COUNTA(_xlfn.UNIQUE(Raw_Data!D2:D5001)) -> 300
A33: CA du plus gros client (€) | B33: =GETPIVOTDATA("Montant Recalculé",Pivot_Summary!$A$4,"Client_ID","CLIENT_0042") -> 356670.77
A34: % du chiffre d'affaires total (%) | B34: =B33/B6 -> 0.13070803
A36: TEST 9 : Cohérence des prix par produit
A37: Variation de prix max (PROD_001) (%) | B37: → Voir la feuille "Anomalies"
A39: TEST 10 : Répartition du chiffre d'affaires
A40: Online (€) | B40: =SUMIF(Raw_Data!N2:N5001,"Online",Raw_Data!K2:K5001) -> 731925.09
A41: Retail (€) | B41: =SUMIF(Raw_Data!N2:N5001,"Retail",Raw_Data!K2:K5001) -> 620426.87
A42: B2B (€) | B42: =SUMIF(Raw_Data!N2:N5001,"B2B",Raw_Data!K2:K5001) -> 688300
A43: Reseller (€) | B43: =SUMIF(Raw_Data!N2:N5001,"Reseller",Raw_Data!K2:K5001) -> 688107.53

Sheet Anomalies
A1: Anomalies détectées - à investiguer
A4: 1. Anomalie : Montants nuls
A6: Invoice_Number | B6: Sale_Date | C6: Année | D6: Client_ID | E6: Product_Code | F6: Product_Name | G6: Category | H6: Quantity | I6: Unit_Price | J6: Amount | K6: Montant Recalculé | L6: Ecarts | M6: Country | N6: Channel
A7: {=_xlfn._xlws.FILTER(Raw_Data!A2:N5001, Raw_Data!H2:H5001 = 0)} -> 2024001052 | B7: 45641 | C7: 2024 | D7: CLIENT_0047 | E7: PROD_003 | F7: USB-C Cable | G7: Electronics | H7: 0 | I7: 13.48 | J7: 0 | K7: 0 | L7: 0 | M7: France | N7: Reseller
A8: 2024001782 | B8: 45589 | C8: 2024 | D8: CLIENT_0042 | E8: PROD_004 | F8: Desk Chair | G8: Furniture | H8: 0 | I8: 330.18 | J8: 0 | K8: 0 | L8: 0 | M8: Switzerland | N8: Online
A9: 2024002254 | B9: 45405 | C9: 2024 | D9: CLIENT_0042 | E9: PROD_008 | F9: Desk Lamp | G9: Furniture | H9: 0 | I9: 80.51 | J9: 0 | K9: 0 | L9: 0 | M9: Sweden | N9: Online
A10: 2024002872 | B10: 45597 | C10: 2024 | D10: CLIENT_0242 | E10: PROD_002 | F10: Wireless Mouse | G10: Electronics | H10: 0 | I10: 44.87 | J10: 0 | K10: 0 | L10: 0 | M10: Italy | N10: B2B
A11: 2024002952 | B11: 45426 | C11: 2024 | D11: CLIENT_0054 | E11: PROD_001 | F11: Laptop Pro | G11: Electronics | H11: 0 | I11: 1251.54 | J11: 0 | K11: 0 | L11: 0 | M11: Spain | N11: Online
A12: 2024002982 | B12: 45494 | C12: 2024 | D12: CLIENT_0116 | E12: PROD_003 | F12: USB-C Cable | G12: Electronics | H12: 0 | I12: 15.12 | J12: 0 | K12: 0 | L12: 0 | M12: Sweden | N12: Reseller
A13: 2024001738 | B13: 45535 | C13: 2024 | D13: CLIENT_0270 | E13: PROD_007 | F13: Keyboard Mechanical | G13: Electronics | H13: 0 | I13: 115.97 | J13: 0 | K13: 0 | L13: 0 | M13: Spain | N13: Reseller
A14: 2024003420 | B14: 45453 | C14: 2024 | D14: CLIENT_0102 | E14: PROD_005 | F14: Standing Desk | G14: Furniture | H14: 0 | I14: 630.37 | J14: 0 | K14: 0 | L14: 0 | M14: Sweden | N14: Online
A15: 2024003435 | B15: 45621 | C15: 2024 | D15: CLIENT_0131 | E15: PROD_004 | F15: Desk Chair | G15: Furniture | H15: 0 | I15: 328.15 | J15: 0 | K15: 0 | L15: 0 | M15: Italy | N15: Retail
A16: 2024003462 | B16: 45368 | C16: 2024 | D16: CLIENT_0019 | E16: PROD_007 | F16: Keyboard Mechanical | G16: Electronics | H16: 0 | I16: 125.64 | J16: 0 | K16: 0 | L16: 0 | M16: Sweden | N16: Online
A17: 2024003619 | B17: 45657 | C17: 2024 | D17: CLIENT_0042 | E17: PROD_003 | F17: USB-C Cable | G17: Electronics | H17: 0 | I17: 14.73 | J17: 0 | K17: 0 | L17: 0 | M17: Germany | N17: Online
A18: 2024004029 | B18: 45341 | C18: 2024 | D18: CLIENT_0270 | E18: PROD_010 | F18: Webcam HD | G18: Electronics | H18: 0 | I18: 97.54 | J18: 0 | K18: 0 | L18: 0 | M18: Spain | N18: Retail
A19: 2024004241 | B19: 45471 | C19: 2024 | D19: CLIENT_0292 | E19: PROD_009 | F19: Phone Stand | G19: Accessories | H19: 0 | I19: 24.22 | J19: 0 | K19: 0 | L19: 0 | M19: Germany | N19: B2B
... A26: 2024005982 | B26: 45646 | C26: 2024 | D26: CLIENT_0173 | E26: PROD_002 | F26: Wireless Mouse | G26: Electronics | H26: 0 | I26: 43.17 | J26: 0 | K26: 0 | L26: 0 | M26: Germany | N26: Retail
A28: 2. Anomalie : Factures en double (Duplicate Invoices)
A30: Invoice_Number | B30: Sale_Date | C30: Année | D30: Client_ID | E30: Product_Code | F30: Product_Name | G30: Category | H30: Quantity | I30: Unit_Price | J30: Amount | K30: Montant Recalculé | L30: Ecarts | M30: Country | N30: Channel
A31: {=_xlfn._xlws.FILTER(Raw_Data!A2:N5001, COUNTIF(Raw_Data!A2:A5001, Raw_Data!A2:A5001) > 1)} -> 2024001027 | B31: 45489 | C31: 2024 | D31: CLIENT_0247 | E31: PROD_004 | F31: Desk Chair | G31: Furniture | H31: 1 | I31: 384.55 | J31: 384.55 | K31: 384.55 | L31: 0 | M31: Switzerland | N31: B2B
A32: 2024001043 | B32: 45547 | C32: 2024 | D32: CLIENT_0128 | E32: PROD_002 | F32: Wireless Mouse | G32: Electronics | H32: 2 | I32: 43.93 | J32: 87.86 | K32: 87.86 | L32: 0 | M32: Netherlands | N32: Retail
A33: 2024001059 | B33: 45541 | C33: 2024 | D33: CLIENT_0010 | E33: PROD_006 | F33: Monitor 27" | G33: Electronics | H33: 2 | I33: 397.9 | J33: 795.8 | K33: 795.8 | L33: 0 | M33: Germany | N33: Reseller
A34: 2024001066 | B34: 45366 | C34: 2024 | D34: CLIENT_0217 | E34: PROD_005 | F34: Standing Desk | G34: Furniture | H34: 4 | I34: 533.5 | J34: 2134 | K34: 2134 | L34: 0 | M34: Switzerland | N34: Reseller
A35: 2024001089 | B35: 45437 | C35: 2024 | D35: CLIENT_0224 | E35: PROD_001 | F35: Laptop Pro | G35: Electronics | H35: 1 | I35: 1129.81 | J35: 1129.81 | K35: 1129.81 | L35: 0 | M35: Sweden | N35: B2B
A36: 2024001114 | B36: 45555 | C36: 2024 | D36: CLIENT_0236 | E36: PROD_003 | F36: USB-C Cable | G36: Electronics | H36: 1 | I36: 15.53 | J36: 15.53 | K36: 15.53 | L36: 0 | M36: Germany | N36: B2B
A37: 2024001059 | B37: 45423 | C37: 2024 | D37: CLIENT_0089 | E37: PROD_010 | F37: Webcam HD | G37: Electronics | H37: 1 | I37: 88.87 | J37: 88.87 | K37: 88.87 | L37: 0 | M37: UK | N37: Online
A38: 2024001139 | B38: 45473 | C38: 2024 | D38: CLIENT_0001 | E38: PROD_006 | F38: Monitor 27" | G38: Electronics | H38: 2 | I38: 390.59 | J38: 781.18 | K38: 781.18 | L38: 0 | M38: Switzerland | N38: B2B
A39: 2024001140 | B39: 45440 | C39: 2024 | D39: CLIENT_0042 | E39: PROD_009 | F39: Phone Stand | G39: Accessories | H39: 2 | I39: 25.77 | J39: 51.54 | K39: 51.54 | L39: 0 | M39: Sweden | N39: Online
A40: 2024001181 | B40: 45295 | C40: 2024 | D40: CLIENT_0210 | E40: PROD_001 | F40: Laptop Pro | G40: Electronics | H40: 3 | I40: 1085.73 | J40: 3257.19 | K40: 3257.19 | L40: 0 | M40: Sweden | N40: Reseller
A41: 2024001184 | B41: 45650 | C41: 2024 | D41: CLIENT_0042 | E41: PROD_004 | F41: Desk Chair | G41: Furniture | H41: 2 | I41: 342.65 | J41: 685.3 | K41: 685.3 | L41: 0 | M41: Switzerland | N41: Retail
A42: 2024001208 | B42: 45561 | C42: 2024 | D42: CLIENT_0192 | E42: PROD_004 | F42: Desk Chair | G42: Furniture | H42: 2 | I42: 320.16 | J42: 640.32 | K42: 640.32 | L42: 0 | M42: France | N42: Retail
A43: 2024001215 | B43: 45490 | C43: 2024 | D43: CLIENT_0181 | E43: PROD_008 | F43: Desk Lamp | G43: Furniture | H43: 4 | I43: 75.25 | J43: 301 | K43: 301 | L43: 0 | M43: UK | N43: Reseller
... A172: 2024002647 | B172: 45297 | C172: 2024 | D172: CLIENT_0193 | E172: PROD_009 | F172: Phone Stand | G172: Accessories | H172: 1 | I172: 23.2 | J172: 23.2 | K172: 23.2 | L172: 0 | M172: France | N172: Retail
A176: 3. Anomalie : Transactions hors période (Out-of-Period)
A179: Invoice_Number | B179: Sale_Date | C179: Année | D179: Client_ID | E179: Product_Code | F179: Product_Name | G179: Category | H179: Quantity | I179: Unit_Price | J179: Amount | K179: Montant Recalculé | L179: Ecarts | M179: Country | N179: Channel
A180: {=_xlfn._xlws.FILTER(Raw_Data!A2:N5001, Raw_Data!C2:C5001 = 2023)} -> 2024001426 | B180: 45282 | C180: 2023 | D180: CLIENT_0070 | E180: PROD_001 | F180: Laptop Pro | G180: Electronics | H180: 4 | I180: 1145.44 | J180: 4581.76 | K180: 4581.76 | L180: 0 | M180: Netherlands | N180: B2B
A181: 2024002568 | B181: 45277 | C181: 2023 | D181: CLIENT_0141 | E181: PROD_007 | F181: Keyboard Mechanical | G181: Electronics | H181: 2 | I181: 123.95 | J181: 247.9 | K181: 247.9 | L181: 0 | M181: Sweden | N181: Online
A182: 2024003427 | B182: 45290 | C182: 2023 | D182: CLIENT_0135 | E182: PROD_006 | F182: Monitor 27" | G182: Electronics | H182: 1 | I182: 399.34 | J182: 399.34 | K182: 399.34 | L182: 0 | M182: UK | N182: Reseller
A183: 2024003446 | B183: 45247 | C183: 2023 | D183: CLIENT_0042 | E183: PROD_004 | F183: Desk Chair | G183: Furniture | H183: 1 | I183: 343.67 | J183: 343.67 | K183: 343.67 | L183: 0 | M183: Germany | N183: B2B
A184: 2024003610 | B184: 45240 | C184: 2023 | D184: CLIENT_0042 | E184: PROD_002 | F184: Wireless Mouse | G184: Electronics | H184: 1 | I184: 46.15 | J184: 46.15 | K184: 46.15 | L184: 0 | M184: Sweden | N184: Online
...

Sheet Pivot_Summary
A2: TOP 10 Clients | E2: REVENUE BY MONTH | I2: REVENUE BY CHANNEL
A4: Row Labels | B4: Sum of Montant Recalculé | E4: Row Labels | F4: Sum of Montant Recalculé | I4: Row Labels | J4: Sum of Montant Recalculé
A5: CLIENT_0042 | B5: 356670.77 | E5: Jan | F5: 227899.51 | I5: B2B | J5: 688300
A6: CLIENT_0070 | B6: 20961.87 | E6: Feb | F6: 203052.25 | I6: Online | J6: 731925.09
A7: CLIENT_0019 | B7: 19777.41 | E7: Mar | F7: 205217.44 | I7: Reseller | J7: 688107.53
A8: CLIENT_0223 | B8: 19676.04 | E8: Apr | F8: 216220.42 | I8: Retail | J8: 620426.87
A9: CLIENT_0246 | B9: 19317.37 | E9: May | F9: 223067.18 | I9: Grand Total | J9: 2728759.5
A10: CLIENT_0065 | B10: 18969.83 | E10: Jun | F10: 230778.35
A11: CLIENT_0088 | B11: 17870.17 | E11: Jul | F11: 232846.36
A12: CLIENT_0208 | B12: 17500.29 | E12: Aug | F12: 263520.37
A13: CLIENT_0253 | B13: 17258.25 | E13: Sep | F13: 226816.71
A14: CLIENT_0137 | B14: 16728.23 | E14: Oct | F14: 238796.6
A15: Grand Total | B15: 524730.23 | E15: Nov | F15: 221614.56
E16: Dec | F16: 238929.74
E17: Grand Total | F17: 2728759.5
